<?xml version="1.0"?>

<robot xmlns:xacro="http://www.ros.org/wiki/xacro">

  <!-- Base -->
  <xacro:macro name="vtol_base"  params="name robot_name **properties">

    <!-- Xacro:Properties-->
    <xacro:insert_block name="properties"/>

    <!-- Attach the robot to the world link if requested -->
    <xacro:if value="$(arg fixed)">
      <gazebo>
        <joint name="${robot_name}_world_joint" type="fixed">
          <parent>${robot_name}_${name}</parent>
          <child>world</child>
        </joint>
      </gazebo>
    </xacro:if>

    <!-- Base link -->
    <!-- TODO : rotate the mesh in yaw using blender, dont to it here-->
    <link name="${robot_name}_${name}">
      <visual>
        <origin xyz="0 0 -0.05" rpy="0 0 ${PI}"/>
        <geometry>
          <!--box size="${L} ${W} ${H}" /-->
          <mesh filename="file://$(find vtol_description)/urdf/base/0_0_0/Base.stl"/>
        </geometry>
        <material name="vtol_material" />
      </visual>
      <collision> <!-- Main Body -->
        <origin xyz="-0.2 0 -0.00" rpy="0 0 0"/>
        <geometry>
          <box size="${L} ${W} ${H}" />
        </geometry>
      </collision>
    </link>

    <!-- Fixed joint to add dummy inertia link -->
    <joint name="${robot_name}_${name}_to_${name}_inertia" type="fixed">
      <parent link="${robot_name}_${name}"/>
      <child link="${robot_name}_${name}_inertia"/>
      <origin xyz="0 0 0" rpy="0 0 0"/>
    </joint>

    <!-- Dummy inertia link, because KDL cannot have inertia on the base link -->
    <link name="${robot_name}_${name}_inertia">
      <inertial>
        <origin   xyz="0 0 0"
                  rpy="0 0 0"/>
        <mass     value="${m_B}"/>
        <inertia  ixx="${B_Ixx_B}" ixy="${B_Ixy_B}" ixz="${B_Ixz_B}"
                  iyy="${B_Iyy_B}" iyz="${B_Iyz_B}" izz="${B_Izz_B}"/>
      </inertial>
    </link>




    <link name="${robot_name}_${name}_wheel_front">
      <inertial>
        <origin   xyz="0 0 0"
                  rpy="0 0 0"/>
        <mass     value="0.001"/>
        <inertia  ixx="0.0000001" ixy="0.000" ixz="0.000"
                  iyy="0.0000001" iyz="0.000" izz="0.0000001"/>
      </inertial>
      <visual>
        <origin xyz="0 0 0" rpy="0 0 0"/>
        <geometry>
          <cylinder length="0.005" radius="0.03"/>
        </geometry>
        <material name="vtol_material" />
      </visual>
      <collision>
        <origin xyz="0 0 0" rpy="0 0 0"/>
        <geometry>
          <cylinder length="0.005" radius="0.03"/>
        </geometry>
      </collision>
    </link>
    <joint name="${robot_name}_${name}_to_${name}_wheel_front" type="continuous">
      <parent link="${robot_name}_${name}"/>
      <child link="${robot_name}_${name}_wheel_front"/>
      <origin xyz="0.1 0 -0.08 " rpy="${PI/2} 0 0"/>
      <axis xyz="0 0 1" />
    </joint>


    <link name="${robot_name}_${name}_wheel_left_hind">
      <inertial>
        <origin   xyz="0 0 0"
                  rpy="0 0 0"/>
        <mass     value="0.001"/>
        <inertia  ixx="0.0000001" ixy="0.000" ixz="0.000"
                  iyy="0.0000001" iyz="0.000" izz="0.0000001"/>
      </inertial>
      <visual>
        <origin xyz="0 0 0" rpy="0 0 0"/>
        <geometry>
          <cylinder length="0.005" radius="0.03"/>
        </geometry>
        <material name="vtol_material" />
      </visual>
      <collision>
        <origin xyz="0 0 0" rpy="0 0 0"/>
        <geometry>
          <cylinder length="0.005" radius="0.03"/>
        </geometry>
      </collision>
    </link>
    <joint name="${robot_name}_${name}_to_${name}_wheel_left_hind" type="continuous">
      <parent link="${robot_name}_${name}"/>
      <child link="${robot_name}_${name}_wheel_left_hind"/>
      <origin xyz="-0.1 -0.2 -0.08 " rpy="${PI/2} 0 0"/>
      <axis xyz="0 0 1" />
    </joint>

    <link name="${robot_name}_${name}_wheel_right_hind">
      <inertial>
        <origin   xyz="0 0 0"
                  rpy="0 0 0"/>
        <mass     value="0.001"/>
        <inertia  ixx="0.0000001" ixy="0.000" ixz="0.000"
                  iyy="0.0000001" iyz="0.000" izz="0.0000001"/>
      </inertial>
      <visual>
        <origin xyz="0 0 0" rpy="0 0 0"/>
        <geometry>
          <cylinder length="0.005" radius="0.03"/>
        </geometry>
        <material name="vtol_material" />
      </visual>
      <collision>
        <origin xyz="0 0 0" rpy="0 0 0"/>
        <geometry>
          <cylinder length="0.005" radius="0.03"/>
        </geometry>
      </collision>
    </link>
    <joint name="${robot_name}_${name}_to_${name}_wheel_right_hind" type="continuous">
      <parent link="${robot_name}_${name}"/>
      <child link="${robot_name}_${name}_wheel_right_hind"/>
      <origin xyz="-0.1 0.2 -0.08 " rpy="${PI/2} 0 0"/>
      <axis xyz="0 0 1" />
    </joint>

    <gazebo>
      <plugin name="gazebo_ros_control"
        filename="libvtol_base_gazebo.so">
        <robot_name>${robot_name}</robot_name>
        <link_name>${robot_name}_${name}</link_name>
        <debug>true</debug>
      </plugin>
    </gazebo>

  </xacro:macro>



</robot>
