<?xml version="1.0"?>

<robot xmlns:xacro="http://www.ros.org/wiki/xacro">

  <!-- Base -->
  <xacro:macro name="aileron"  params="robot_name base_name side **properties">

    <!-- Xacro:Properties-->
    <xacro:insert_block name="properties"/>
    <xacro:property name="left"  value="${int(side.startswith('l'))*2-1}"/>

    <!-- Rotor link -->
    <link name="${robot_name}_aileron_${side}">
      <visual>
        <origin xyz="0 ${left *w_aileron/2} 0" rpy="0 0 0"/>
        <geometry>
          <box size="${l_aileron} ${w_aileron} ${h_aileron}"/>
        </geometry>
      </visual>
      <collision> <!-- Main Body -->
        <origin xyz="0 0 0" rpy="0 0 0"/>
        <geometry>
          <box size="${l_aileron} ${w_aileron} ${h_aileron}"/>
        </geometry>
      </collision>
      <inertial>
        <origin   xyz="0 0 0"
                  rpy="0 0 0"/>
        <mass     value="${m_aileron}"/>
        <inertia  ixx="${Ixx_aileron}" ixy="${Ixy_aileron}" ixz="${Ixz_aileron}"
                iyy="${Iyy_aileron}" iyz="${Iyz_aileron}" izz="${Izz_aileron}"/>
      </inertial>
    </link>

    <joint name="${robot_name}_aileron_${side}" type="revolute">
      <parent link="${base_name}"/>
      <child link="${robot_name}_aileron_${side}"/>
      <origin xyz="${x_aileron} ${left * y_aileron} ${z_aileron}" rpy="0 0 ${left * yaw_aileron}"/>
      <axis xyz="1 0 0" />
      <limit effort="30" velocity="1.0" lower="-${PI/6}" upper="${PI/6}" />
    </joint>

    <transmission name="${robot_name}_rotor_transmission_front_${side}">
      <type>transmission_interface/SimpleTransmission</type>
      <joint name="${robot_name}_aileron_${side}">
        <hardwareInterface>hardware_interface/PositionJointInterface</hardwareInterface>
      </joint>
      <actuator name="${robot_name}_rotor_${side}_front_actuator">
        <mechanicalReduction>1</mechanicalReduction>
        <hardwareInterface>hardware_interface/PositionJointInterface</hardwareInterface>
      </actuator>
    </transmission>


  </xacro:macro>



</robot>
